<robot name="GeneratedRobot">
  <link name="base_link">
    <visual>
      <origin xyz="0 0 0.5" rpy="0 0 0" />
      <geometry>
        <box size="0.46796655054122455 0.2399913173327918 1.0514391556143112" />
      </geometry>
      <material name="base_material">
        <color rgba="0.2 0.2 0.2 1" />
      </material>
    </visual>
    <collision>
      <origin xyz="0 0 0.5" rpy="0 0 0" />
      <geometry>
        <box size="0.46796655054122455 0.2399913173327918 1.0514391556143112" />
      </geometry>
    </collision>
    <inertial>
      <origin xyz="0 0 0.5" rpy="0 0 0" />
      <mass value="10" />
      <inertia ixx="0.1" ixy="0" ixz="0" iyy="0.1" iyz="0" izz="0.1" />
    </inertial>
  </link>
  
  <link name="arm1">
    <visual>
      <origin xyz="0 0 0" rpy="0 0 0" />
      <geometry>
        <box size="0.05 0.05 0.5" />
      </geometry>
      <material name="arm_material">
        <color rgba="0.5 0.5 0.5 1" />
      </material>
    </visual>
    <collision>
      <origin xyz="0 0 0" rpy="0 0 0" />
      <geometry>
        <box size="0.05 0.05 0.5" />
      </geometry>
    </collision>
    <inertial>
      <origin xyz="0 0 0" rpy="0 0 0" />
      <mass value="0.1" />
      <inertia ixx="0.0001" ixy="0" ixz="0" iyy="0.0001" iyz="0" izz="0.0001" />
    </inertial>
  </link>

  <link name="arm2">
    <visual>
      <origin xyz="0 0 0" rpy="0 0 0" />
      <geometry>
        <box size="0.05 0.05 0.5" />
      </geometry>
      <material name="arm_material" />
    </visual>
    <collision>
      <origin xyz="0 0 0" rpy="0 0 0" />
      <geometry>
        <box size="0.05 0.05 0.5" />
      </geometry>
    </collision>
    <inertial>
      <origin xyz="0 0 0" rpy="0 0 0" />
      <mass value="0.1" />
      <inertia ixx="0.0001" ixy="0" ixz="0" iyy="0.0001" iyz="0" izz="0.0001" />
    </inertial>
  </link>
  
  <link name="cube2">
    <visual>
      <origin xyz="0 0 0" rpy="0 0 0" />
      <geometry>
        <box size="0.32 0.24 1.05" />
      </geometry>
      <material name="cube2_material">
        <color rgba="0.11443537381770343 0.11193242782769693 0.23455058215026167 1" />
      </material>
    </visual>
    <collision>
      <origin xyz="0 0 0" rpy="0 0 0" />
      <geometry>
        <box size="0.32 0.24 1.05" />
      </geometry>
    </collision>
    <inertial>
      <origin xyz="0 0 0" rpy="0 0 0" />
      <mass value="10" />
      <inertia ixx="0.1" ixy="0" ixz="0" iyy="0.1" iyz="0" izz="0.1" />
    </inertial>
  </link>

  <link name="cube3">
    <visual>
      <origin xyz="0 0 0" rpy="0 0 0" />
      <geometry>
        <box size="0.32 0.24 1.05" />
      </geometry>
      <material name="cube3_material">
        <color rgba="0.026241221889696346 0.13286832154414627 0.4019777798219466 1" />
      </material>
    </visual>
    <collision>
      <origin xyz="0 0 0" rpy="0 0 0" />
      <geometry>
        <box size="0.32 0.24 1.05" />
      </geometry>
    </collision>
    <inertial>
      <origin xyz="0 0 0" rpy="0 0 0" />
      <mass value="10" />
      <inertia ixx="0.1" ixy="0" ixz="0" iyy="0.1" iyz="0" izz="0.1" />
    </inertial>
  </link>

  <joint name="base_link_to_arm1" type="prismatic">
    <parent link="base_link" />
    <child link="arm1" />
    <origin xyz="0.234 0 0.5" rpy="0 0 0" />
    <axis xyz="0 0 1"/>
    <limit effort="1000.0" lower="0.0" upper="0.5" velocity="0.5"/>
  </joint>

  <joint name="arm1_to_cube2" type="revolute">
    <parent link="arm1" />
    <child link="cube2" />
    <origin xyz="0.185 0 0" rpy="0 0 0" />
    <axis xyz="1 0 0"/>
    <limit effort="10.0" lower="-1.57" upper="1.57" velocity="10"/>
  </joint>

  <joint name="base_link_to_arm2" type="prismatic">
    <parent link="base_link" />
    <child link="arm2" />
    <origin xyz="-0.234 0 0.5" rpy="0 0 0" />
    <axis xyz="0 0 1"/>
    <limit effort="1000.0" lower="0.0" upper="0.5" velocity="0.5"/>
  </joint>

  <joint name="arm2_to_cube3" type="revolute">
    <parent link="arm2" />
    <child link="cube3" />
    <origin xyz="-0.185 0 0" rpy="0 0 0" />
    <axis xyz="1 0 0"/>
    <limit effort="10.0" lower="-1.57" upper="1.57" velocity="10"/>
  </joint>

  <ros2_control name="GeneratedRobot_control" type="system">
    <hardware>
      <plugin>gazebo_ros2_control/GazeboSystem</plugin>
    </hardware>
    <joint name="base_link_to_arm1">
      <command_interface name="position">
        <param name="min">0.0</param>
        <param name="max">0.5</param>
      </command_interface>
      <state_interface name="position"/>
      <state_interface name="velocity"/>
    </joint>
    <joint name="arm1_to_cube2">
      <command_interface name="position">
        <param name="min">-1.57</param>
        <param name="max">1.57</param>
      </command_interface>
      <state_interface name="position"/>
      <state_interface name="velocity"/>
    </joint>
    <joint name="base_link_to_arm2">
      <command_interface name="position">
        <param name="min">0.0</param>
        <param name="max">0.5</param>
      </command_interface>
      <state_interface name="position"/>
      <state_interface name="velocity"/>
    </joint>
    <joint name="arm2_to_cube3">
      <command_interface name="position">
        <param name="min">-1.57</param>
        <param name="max">1.57</param>
      </command_interface>
      <state_interface name="position"/>
      <state_interface name="velocity"/>
    </joint>
  </ros2_control>
</robot>